Workbook

Sheet Final Batch with projects
A1: Nos | B1: UID | C1: Email | D1: Name | E1: Current Batch | F1: Capstone Batch Allocation | G1: Stream | H1: Project allocation | I1: Description
A2: 1 | B2: 249440 | C2: ashwin.ckocheril@ust.com | D2: Ashwin C Kocheril | E2: batch 1 | F2: Batch 1 | G2: JAVA | H2: Daily Events Tracker Application | I2: =VLOOKUP(H2,'Trainer Alocation to projects'!B:C,2,0) -> Admin :- Add Task/View Task​/Update Task​/Delete Task​ User - Search Task/update the status of the task, add comments ​ | J2: JAG
A3: 1 | B3: 248764 | C3: ajayakrishnan.j@ust.com | D3: Ajayakrishnan J | E3: batch 1 | F3: Batch 1 | G3: JAVA | H3: Daily Events Tracker Application | J3: JAG
A4: 1 | B4: 248761 | C4: athira.radhakrishnan2@ust.com | D4: Athira Radhakrishnan | E4: batch 1 | F4: Batch 1 | G4: JAVA | H4: Daily Events Tracker Application | J4: JAG
A5: 2 | B5: 248726 | C5: abin.james@ust.com | D5: Abin James | E5: batch 1 | F5: Batch 2 | G5: JAVA | H5: Music Listing and Rating Application | I5: =VLOOKUP(H5,'Trainer Alocation to projects'!B:C,2,0) -> Admin -add, edit, delete, view audio details​ User – view audio details, search, view rating, add rating
A6: 2 | B6: 249394 | C6: rohith.raju@ust.com | D6: Rohith Raju | E6: batch 2 | F6: Batch 2 | G6: JAVA | H6: Music Listing and Rating Application
A7: 2 | B7: 248792 | C7: karthik.venukumar@ust.com | D7: KARTHIK VENUKUMAR | E7: batch 1 | F7: Batch 2 | G7: JAVA | H7: Music Listing and Rating Application | W7: 13
A8: 3 | B8: 248753 | C8: niranj.rajesh@ust.com | D8: Niranj Rajesh | E8: batch 1 | F8: Batch 3 | G8: JAVA | H8: Restaurant Management Application | I8: =VLOOKUP(H8,'Trainer Alocation to projects'!B:C,2,0) -> The Admin can add/view/update/delete the food/menu details The user can view the menu Details​/order/rate/search menu | J8: JAG | W8: 10 | X8: 3
A9: 3 | B9: 248803 | C9: sidharth.pk@ust.com | D9: Sidharth p k | E9: batch 2 | F9: Batch 3 | G9: JAVA | H9: Restaurant Management Application | J9: JAG
A10: 3 | B10: 248742 | C10: abitha.baby@ust.com | D10: Abitha Baby | E10: batch 2 | F10: Batch 3 | G10: JAVA | H10: Restaurant Management Application | J10: JAG
A11: 4 | B11: 249528 | C11: ken.binoy@ust.com | D11: Ken Binoy | E11: batch 1 | F11: Batch 4 | G11: JAVA | H11: Doctors Listing and Appointment Application | I11: =VLOOKUP(H11,'Trainer Alocation to projects'!B:C,2,0) -> Admin can Add/Update/Delete/View Doctors User list doctors/Search/Rate/book appointment
A12: 4 | B12: 248790 | C12: arathi.kannanranjitha@ust.com | D12: Arathi Kannan Ranjitha | E12: batch 2 | F12: Batch 4 | G12: JAVA | H12: Doctors Listing and Appointment Application
A13: 4 | B13: 248750 | C13: vishnu.kumarh@ust.com | D13: Vishnu Kumar H | E13: batch 1 | F13: Batch 4 | G13: JAVA | H13: Doctors Listing and Appointment Application
A14: 5 | B14: 248769 | C14: srinidhi.dinkarpai@ust.com | D14: Srinidhi Dinkar Pai | E14: batch 1 | F14: Batch 5 | G14: JAVA | H14: E-Learning Platform | I14: =VLOOKUP(H14,'Trainer Alocation to projects'!B:C,2,0) -> The program will accept the course and booking for a course Admin can Add/View/Update/Delete the course details​ User can view courses, search course, rate and register for the course​ | J14: JAG
A15: 5 | B15: 249529 | C15: aiswarya.p@ust.com | D15: AISWARYA P | E15: batch 1 | F15: Batch 5 | G15: JAVA | H15: E-Learning Platform | J15: JAG | W15: 7
A16: 5 | B16: 248740 | C16: tony.kurian1@ust.com | D16: Tony Kurian | E16: batch 2 | F16: Batch 5 | G16: JAVA | H16: E-Learning Platform | J16: JAG
A17: 6 | B17: 248734 | C17: afeefa.kollamparambilhamza@ust.com | D17: Afeefa Kollamparambil Hamza | E17: batch 1 | F17: Batch 6 | G17: JAVA | H17: Bus Ticket Booking Application | I17: =VLOOKUP(H17,'Trainer Alocation to projects'!B:C,2,0) -> 1. The program will accept the Bus & Booking Details from the console​ 2. Admin can Add/View/Update/Delete Bus details​ and number of tickects available for a specific date. Make an Assumption when bus is created, auto create tickets for next 3 days 3. User can Book/View/Cancel the tickets/ search bus
A18: 6 | B18: 248738 | C18: anakha.parameswaransreekumari@ust.com | D18: Anakha Parameswaran Sreekumari | E18: batch 1 | F18: Batch 6 | G18: JAVA | H18: Bus Ticket Booking Application
A19: 6 | B19: 248719 | C19: reenu.rachelthomas@ust.com | D19: Reenu Rachel Thomas | E19: batch 1 | F19: Batch 6 | G19: JAVA | H19: Bus Ticket Booking Application
A20: 7 | B20: 248775 | C20: amal.thekkelsobhanakumari@ust.com | D20: Amal Thekkel Sobhanakumari | E20: batch 2 | F20: Batch 7 | G20: JAVA | H20: Project management Application | I20: =VLOOKUP(H20,'Trainer Alocation to projects'!B:C,2,0) -> Admin-can add/update/list/ delete project and task​ user can see the task assigned to him/search task/ update status/ add comments. | J20: JAG
A21: 7 | B21: 248819 | C21: mufeed.unniyengal@ust.com | D21: Mufeed Unniyengal | E21: batch 1 | F21: Batch 7 | G21: JAVA | H21: Project management Application | J21: JAG
A22: 7 | B22: 248799 | C22: aswin.ranjithtr@ust.com | D22: Aswin Ranjith T R | E22: batch 1 | F22: Batch 7 | G22: JAVA | H22: Project management Application | J22: JAG
A23: 8 | B23: 249581 | C23: abhirami.ac@ust.com | D23: Abhirami AC | E23: batch 1 | F23: Batch 8 | G23: JAVA | H23: Online Shopping Management System | I23: =VLOOKUP(H23,'Trainer Alocation to projects'!B:C,2,0) -> Admin can do crud on the Products details.​ User can view the products ,add products to the cart and delete the product from the cart and rate product
A24: 8 | B24: 248751 | C24: ebin.muttath@ust.com | D24: Ebin Muttath | E24: batch 2 | F24: Batch 8 | G24: JAVA | H24: Online Shopping Management System
A25: 8 | B25: 248825 | C25: ajay.cm@ust.com | D25: Ajay C M | E25: batch 1 | F25: Batch 8 | G25: JAVA | H25: Online Shopping Management System
A26: 9 | B26: 248735 | C26: aleena.kuriakose@ust.com | D26: Aleena Kuriakose | E26: batch 1 | F26: Batch 9 | G26: JAVA | H26: Parcel booking and Tracker Application | I26: =VLOOKUP(H26,'Trainer Alocation to projects'!B:C,2,0) -> The program will accept the Parcel details from the console The user sees the list of his parcel, track current location, search parcel,request call back Admin can Add parcel details​/View parcel list​/Delete/Update parcel​ | J26: JAG
A27: 9 | B27: 248765 | C27: uma.am@ust.com | D27: Uma A M | E27: batch 1 | F27: Batch 9 | G27: JAVA | H27: Parcel booking and Tracker Application | J27: JAG
A28: 9 | B28: 248789 | C28: ashwin.ashok@ust.com | D28: Ashwin Ashok | E28: batch 1 | F28: Batch 9 | G28: JAVA | H28: Parcel booking and Tracker Application | J28: JAG
A29: 10 | B29: 248778 | C29: sidharth.sanil@ust.com | D29: Sidharth Ayyappan Sanil | E29: batch 1 | F29: Batch 10 | G29: JAVA | H29: Online Food Ordering Application | I29: =VLOOKUP(H29,'Trainer Alocation to projects'!B:C,2,0) -> The program will accept the Order details from the User​ The Admin Add/View/Update the Order details.​ The Kitchen staff should be able to see the order assingned to them, update the order status, search the order
A30: 10 | B30: 249578 | C30: rejin.mathews@ust.com | D30: Rejin Mathews | E30: batch 2 | F30: Batch 10 | G30: JAVA | H30: Online Food Ordering Application
A31: 10 | B31: 248793 | C31: anagha.biju@ust.com | D31: Anagha biju | E31: batch 2 | F31: Batch 10 | G31: JAVA | H31: Online Food Ordering Application
A32: 11 | B32: 248723 | C32: akhila.madhavan@ust.com | D32: Akhila Madhavan | E32: batch 2 | F32: Batch 11 | G32: JAVA | H32: Movie Listing and Rating Application | I32: =VLOOKUP(H32,'Trainer Alocation to projects'!B:C,2,0) -> Admin can add/view/update/deletemovies User :- view movie list/search by movie name & release date/ view rating/add rating | J32: JAG
A33: 11 | B33: 248739 | C33: ansiya.salam@ust.com | D33: Ansiya Salam | E33: batch 2 | F33: Batch 11 | G33: JAVA | H33: Movie Listing and Rating Application | J33: JAG
A34: 11 | B34: 249416 | C34: ashna.shamsudeen@ust.com | D34: Ashna Shamsudeen | E34: batch 2 | F34: Batch 11 | G34: JAVA | H34: Movie Listing and Rating Application | J34: JAG
A35: 12 | B35: 248727 | C35: antu.jilson@ust.com | D35: Antu Jilson | E35: batch 1 | F35: Batch 12 | G35: JAVA | H35: Bug Tracker Application | I35: =VLOOKUP(H35,'Trainer Alocation to projects'!B:C,2,0) -> The program will accept Bugs for different projects Admin - crud on the bugs The user then can search for a Bug based on name, Project and Status​. The user can update the status of the Bug The user should be able to view all the Bugs raised under his name and Bugs in a Project​
A36: 12 | B36: 248730 | C36: fibin.pious@ust.com | D36: Fibin Pious | E36: batch 1 | F36: Batch 12 | G36: JAVA | H36: Bug Tracker Application
A37: 12 | B37: 249414 | C37: ancy.pachenkunju@ust.com | D37: Ancy P Achenkunju | E37: batch 2 | F37: Batch 12 | G37: JAVA | H37: Bug Tracker Application
A38: 13 | B38: 249532 | C38: jalaneela.kalyan@ust.com | D38: kalyan Jalaneela | E38: batch 1 | F38: Batch 13 | G38: JAVA | H38: Online Book Store Application | I38: =VLOOKUP(H38,'Trainer Alocation to projects'!B:C,2,0) -> Admin - Add Book/Update/View/Delete User​ - Search Book/List Book/rate book/view book ratings
A39: 13 | B39: 249422 | C39: nawal.asiyaat@ust.com | D39: nawal Asiya AT | E39: batch 2 | F39: Batch 13 | G39: JAVA | H39: Online Book Store Application
A40: 13 | B40: 249387 | C40: shyma.paul@ust.com | D40: SHYMA PAUL | E40: batch 2 | F40: Batch 13 | G40: JAVA | H40: Online Book Store Application
...

Sheet Trainer Alocation to projects
A1: Trainer Name | B1: Project Name | C1: Description
A2: Jagadeesh | B2: Daily Events Tracker Application | C2: Admin :- Add Task/View Task​/Update Task​/Delete Task​ User - Search Task/update the status of the task, add comments ​
A3: Ramanuj | B3: Music Listing and Rating Application | C3: Admin -add, edit, delete, view audio details​ User – view audio details, search, view rating, add rating
A4: Jagadeesh | B4: Restaurant Management Application | C4: The Admin can add/view/update/delete the food/menu details The user can view the menu Details​/order/rate/search menu
A5: Ramanuj | B5: Doctors Listing and Appointment Application | C5: Admin can Add/Update/Delete/View Doctors User list doctors/Search/Rate/book appointment
A6: Jagadeesh | B6: E-Learning Platform | C6: The program will accept the course and booking for a course Admin can Add/View/Update/Delete the course details​ User can view courses, search course, rate and register for the course​
A7: Ramanuj | B7: Bus Ticket Booking Application | C7: 1. The program will accept the Bus & Booking Details from the console​ 2. Admin can Add/View/Update/Delete Bus details​ and number of tickects available for a specific date. Make an Assumption when bus is created, auto create tickets for next 3 days 3. User can Book/View/Cancel the tickets/ search bus
A8: Jagadeesh | B8: Project management Application | C8: Admin-can add/update/list/ delete project and task​ user can see the task assigned to him/search task/ update status/ add comments.
A9: Ramanuj | B9: Online Shopping Management System | C9: Admin can do crud on the Products details.​ User can view the products ,add products to the cart and delete the product from the cart and rate product
A10: Jagadeesh | B10: Parcel booking and Tracker Application | C10: The program will accept the Parcel details from the console The user sees the list of his parcel, track current location, search parcel,request call back Admin can Add parcel details​/View parcel list​/Delete/Update parcel​
A11: Ramanuj | B11: Online Food Ordering Application | C11: The program will accept the Order details from the User​ The Admin Add/View/Update the Order details.​ The Kitchen staff should be able to see the order assingned to them, update the order status, search the order
A12: Jagadeesh | B12: Movie Listing and Rating Application | C12: Admin can add/view/update/deletemovies User :- view movie list/search by movie name & release date/ view rating/add rating
... A15: Ramanuj | B15: Online Book Store Application | C15: Admin - Add Book/Update/View/Delete User​ - Search Book/List Book/rate book/view book ratings
B16: Employee Management Application | C16: The program will accept the Employee & project details from the console ​ The Admin can Add/View/Update Employee Details User can view his details and update details like addresss/personal info, apply for project, provide feed back/write comments for his project

Sheet deliveberals for Foundation
A1: Items | B1: Mile Stones | C1: Resources | D1: Milestones
A2: 1 | B2: Use case document | C2: Upload to git hub | D2: Foundation
A3: 2 | B3: Task tracker/user stories with target dates | C3: Upload to git hub | D3: Rolling
A4: 3 | B4: UML diagram (use case diagram/sequence diagram) | C4: Upload to git hub | D4: Foundation
A5: 4 | B5: ER diagram | C5: Upload to git hub | D5: Foundation
A6: 5 | B6: Project structure | C6: Git hub | D6: Foundation
A7: 6 | B7: UI wire frame/ppt of look and feel | C7: Upload to git hub | D7: Foundation
A8: 7 | B8: Api development | C8: Git hub | D8: Rolling
A9: 8 | B9: Postman collection of Api | C9: Upload to git hub | D9: Rolling
